Workbook
Name value_list: коэф_произв[Значение]
Name value_list: коэф_произв[Значение]
Name value_list: коэф_произв[Значение]
Name value_list: коэф_произв[Значение]
Name value_list: коэф_произв[Значение]
Name value_list: коэф_произв[Значение]
Name value_list: коэф_произв[Значение]
Name value_list: коэф_произв[Значение]
Name value_list: коэф_произв[Значение]
Name долл: dict!$G$1
Name Класс: Таблица2[Класс]
Name Класс: Таблица2[Класс]
Name Класс: Таблица2[Класс]
Name Класс: Таблица2[Класс]
Name Класс: Таблица2[Класс]
Name Класс: Таблица2[Класс]
Name Класс: Таблица2[Класс]
Name Класс: Таблица2[Класс]
Name Класс: Таблица2[Класс]
Name Объект_оценки_аналог: Таблица2[Объект оценки/ аналог]
Name Объект_оценки_аналог: Таблица2[Объект оценки/ аналог]
Name Объект_оценки_аналог: Таблица2[Объект оценки/ аналог]
Name Объект_оценки_аналог: Таблица2[Объект оценки/ аналог]
Name Объект_оценки_аналог: Таблица2[Объект оценки/ аналог]
Name Объект_оценки_аналог: Таблица2[Объект оценки/ аналог]
Name Объект_оценки_аналог: Таблица2[Объект оценки/ аналог]
Name Объект_оценки_аналог: Таблица2[Объект оценки/ аналог]
Name Объект_оценки_аналог: Таблица2[Объект оценки/ аналог]
Name Площадь: Таблица2[Площадь, м2]
Name Площадь: Таблица2[Площадь, м2]
Name Площадь: Таблица2[Площадь, м2]
Name Площадь: Таблица2[Площадь, м2]
Name Площадь: Таблица2[Площадь, м2]
Name Площадь: Таблица2[Площадь, м2]
Name Площадь: Таблица2[Площадь, м2]
Name Площадь: Таблица2[Площадь, м2]
Name Площадь: Таблица2[Площадь, м2]

Sheet dict
A1: Характеристика | B1: Тип | C1: Значение | D1: Коэффициент | F1: доллар | G1: 87.45
A2: Высота | B2: гражд | C2: До 2,6 м. | D2: 0.6
A3: Высота | B3: гражд | C3: 2,6-3,2 м. | D3: 0.7
A4: Высота | B4: гражд | C4: 3,2-4 м. | D4: 0.8
A5: Высота | B5: гражд | C5: Более 4 м. (условно - 5 м в среднем) | D5: 1
A6: Архитектура | B6: гражд | C6: Устаревшая | D6: 0.8
A7: Архитектура | B7: гражд | C7: Устаревшая/ Современная | D7: 0.9
A8: Архитектура | B8: гражд | C8: Современная | D8: 1
A9: Конструкция | B9: гражд | C9: Некапитальная | D9: 0.8
A10: Конструкция | B10: гражд | C10: Смешанная | D10: 0.9
A11: Конструкция | B11: гражд | C11: Капитальная | D11: 1
A12: Планировка | B12: гражд | C12: Свободная | D12: 0.9
A13: Планировка | B13: гражд | C13: Смешанная | D13: 0.95
... A38: Инженерное оснащение | B38: произв | C38: Высокое (дополнителньые системы (вентиляция, противопожарная безопасность, бесключевой доступ), возможна подводка газа, | D38: 1

Sheet Таблица объектов
A1: Объект оценки/ аналог | B1: Площадь, м2 | C1: Объект | D1: Тип | E1: Высота | F1: Высота коэф. | G1: Наличие / Возможность кран-балки | H1: Наличие / Возможность кран-балки коэф. | I1: Конструкция | J1: Конструкция коэф. | K1: Полы | L1: Полы коэф. | M1: Инженерное оснащение | N1: Инженерное оснащение коэф. | O1: Архитектура | P1: Архитектура коэф. | Q1: Планировка | R1: Планировка коэф. | S1: Уровень отделки | T1: Уровень отделки коэф. | U1: Капитальность | V1: Класс | W1: Площадь, взвешенная по капитальности | X1: Состояние | Y1: состояние взвешенное | Z1: состояние взвешенное скорректир. На капитальность | AB1: из расчёта затратного
A2: Объект оценки 1 | B2: 1113.8 | C2: Нежилое помещение (Склады) | D2: произв | E2: 3-5 м. | F2: {=_xlfn.XLOOKUP(1,(Таблица2[[#This Row],[Тип]]=коэф_произв[Тип])*(Таблица2[[#This Row],[Высота]]=коэф_произв[Значение])*('Таблица объектов'!E$1=коэф_произв[Характеристика]),коэф_произв[Коэффициент],"",0)} -> 0.6 | G2: Не установлено (по умолчанию) | H2: {=_xlfn.XLOOKUP(1,(Таблица2[[#This Row],[Тип]]=коэф_произв[Тип])*(Таблица2[[#This Row],[Наличие / Возможность кран-балки]]=коэф_произв[Значение])*('Таблица объектов'!G$1=коэф_произв[Характеристика]),коэф_произв[Коэффициент],"",0)} -> 0.95 | I2: Блочные по железобетонному каркасу, без утепления | J2: {=_xlfn.XLOOKUP(1,(Таблица2[[#This Row],[Тип]]=коэф_произв[Тип])*(Таблица2[[#This Row],[Конструкция]]=коэф_произв[Значение])*('Таблица объектов'!I$1=коэф_произв[Характеристика]),коэф_произв[Коэффициент],"",0)} -> 0.7 | K2: Простые | L2: {=_xlfn.XLOOKUP(1,(Таблица2[[#This Row],[Тип]]=коэф_произв[Тип])*(Таблица2[[#This Row],[Полы]]=коэф_произв[Значение])*('Таблица объектов'!K$1=коэф_произв[Характеристика]),коэф_произв[Коэффициент],"",0)} -> 0.9 | M2: Отсутствует или минимальное (минимальная разводка освещения, водопровода) | N2: {=_xlfn.XLOOKUP(1,(Таблица2[[#This Row],[Тип]]=коэф_произв[Тип])*(Таблица2[[#This Row],[Инженерное оснащение]]=коэф_произв[Значение])*('Таблица объектов'!M$1=коэф_произв[Характеристика]),коэф_произв[Коэффициент],"",0)} -> 0.8 | P2: {=_xlfn.XLOOKUP(1,(Таблица2[[#This Row],[Тип]]=коэф_произв[Тип])*(Таблица2[[#This Row],[Архитектура]]=коэф_произв[Значение])*('Таблица объектов'!O$1=коэф_произв[Характеристика]),коэф_произв[Коэффициент],"",0)} | R2: {=_xlfn.XLOOKUP(1,(Таблица2[[#This Row],[Тип]]=коэф_произв[Тип])*(Таблица2[[#This Row],[Планировка]]=коэф_произв[Значение])*('Таблица объектов'!Q$1=коэф_произв[Характеристика]),коэф_произв[Коэффициент],"",0)} | T2: {=_xlfn.XLOOKUP(1,(Таблица2[[#This Row],[Тип]]=коэф_произв[Тип])*(Таблица2[[#This Row],[Уровень отделки]]=коэф_произв[Значение])*('Таблица объектов'!S$1=коэф_произв[Характеристика]),коэф_произв[Коэффициент],"",0)} | U2: =IF(Таблица2[[#This Row],[Тип]]="прочие",0.05,PRODUCT(Таблица2[[#This Row],[Уровень отделки коэф.]],Таблица2[[#This Row],[Планировка коэф.]],Таблица2[[#This Row],[Архитектура коэф.]],Таблица2[[#This Row],[Инженерное оснащение коэф.]],Таблица2[[#This Row],[Полы коэф.]],Таблица2[[#This Row],[Конструкция коэф.]],Таблица2[[#This Row],[Наличие / Возможность кран-балки коэф.]],Таблица2[[#This Row],[Высота коэф.]])) -> 0.28728 | V2: =IF(Таблица2[[#This Row],[Тип]]="произв",IF(Таблица2[[#This Row],[Капитальность]]<0.33,"произв класс 4",IF(Таблица2[[#This Row],[Капитальность]]<0.55,"произв класс 3",IF(Таблица2[[#This Row],[Капитальность]]<0.77,"произв класс 2","произв класс 1"))),IF(Таблица2[[#This Row],[Тип]]="гражд",IF(Таблица2[[#This Row],[Капитальность]]<0.33,"гражд класс 4",IF(Таблица2[[#This Row],[Капитальность]]<0.55,"гражд класс 3",IF(Таблица2[[#This Row],[Капитальность]]<0.77,"гражд класс 2","гражд класс 1"))),"прочие")) -> произв класс 4 | W2: =Таблица2[[#This Row],[Площадь, м2]]*Таблица2[[#This Row],[Капитальность]] -> 319.97246 | X2: =IF(AB2<4%,5,IF(AB2<9%,4.5,IF(AB2<14%,4,IF(AB2<24%,3.5,IF(AB2<40%,3,IF(AB2<60%,2.5,IF(AB2<80%,2,1))))))) -> 3 | Y2: =X2*Таблица2[[#This Row],[Площадь, м2]] -> 3341.4 | Z2: =Y2*Таблица2[[#This Row],[Капитальность]] -> 959.91739 | AB2: 0.364
A3: Объект оценки 1 | B3: 9482.1 | C3: Нежилое помещение с пристройкой (Склады) | D3: произв | E3: Более 8 м. (условно - 10 м в среднем) | F3: {=_xlfn.XLOOKUP(1,(Таблица2[[#This Row],[Тип]]=коэф_произв[Тип])*(Таблица2[[#This Row],[Высота]]=коэф_произв[Значение])*('Таблица объектов'!E$1=коэф_произв[Характеристика]),коэф_произв[Коэффициент],"",0)} -> 1 | G3: Да | H3: {=_xlfn.XLOOKUP(1,(Таблица2[[#This Row],[Тип]]=коэф_произв[Тип])*(Таблица2[[#This Row],[Наличие / Возможность кран-балки]]=коэф_произв[Значение])*('Таблица объектов'!G$1=коэф_произв[Характеристика]),коэф_произв[Коэффициент],"",0)} -> 1 | I3: Блочные бескаркасные или металлокаркасные холодные | J3: {=_xlfn.XLOOKUP(1,(Таблица2[[#This Row],[Тип]]=коэф_произв[Тип])*(Таблица2[[#This Row],[Конструкция]]=коэф_произв[Значение])*('Таблица объектов'!I$1=коэф_произв[Характеристика]),коэф_произв[Коэффициент],"",0)} -> 0.5 | K3: Усиленные для техники или специальные | L3: {=_xlfn.XLOOKUP(1,(Таблица2[[#This Row],[Тип]]=коэф_произв[Тип])*(Таблица2[[#This Row],[Полы]]=коэф_произв[Значение])*('Таблица объектов'!K$1=коэф_произв[Характеристика]),коэф_произв[Коэффициент],"",0)} -> 1 | M3: Отсутствует или минимальное (минимальная разводка освещения, водопровода) | N3: {=_xlfn.XLOOKUP(1,(Таблица2[[#This Row],[Тип]]=коэф_произв[Тип])*(Таблица2[[#This Row],[Инженерное оснащение]]=коэф_произв[Значение])*('Таблица объектов'!M$1=коэф_произв[Характеристика]),коэф_произв[Коэффициент],"",0)} -> 0.8 | P3: {=_xlfn.XLOOKUP(1,(Таблица2[[#This Row],[Тип]]=коэф_произв[Тип])*(Таблица2[[#This Row],[Архитектура]]=коэф_произв[Значение])*('Таблица объектов'!O$1=коэф_произв[Характеристика]),коэф_произв[Коэффициент],"",0)} | R3: {=_xlfn.XLOOKUP(1,(Таблица2[[#This Row],[Тип]]=коэф_произв[Тип])*(Таблица2[[#This Row],[Планировка]]=коэф_произв[Значение])*('Таблица объектов'!Q$1=коэф_произв[Характеристика]),коэф_произв[Коэффициент],"",0)} | T3: {=_xlfn.XLOOKUP(1,(Таблица2[[#This Row],[Тип]]=коэф_произв[Тип])*(Таблица2[[#This Row],[Уровень отделки]]=коэф_произв[Значение])*('Таблица объектов'!S$1=коэф_произв[Характеристика]),коэф_произв[Коэффициент],"",0)} | U3: =IF(Таблица2[[#This Row],[Тип]]="прочие",0.05,PRODUCT(Таблица2[[#This Row],[Уровень отделки коэф.]],Таблица2[[#This Row],[Планировка коэф.]],Таблица2[[#This Row],[Архитектура коэф.]],Таблица2[[#This Row],[Инженерное оснащение коэф.]],Таблица2[[#This Row],[Полы коэф.]],Таблица2[[#This Row],[Конструкция коэф.]],Таблица2[[#This Row],[Наличие / Возможность кран-балки коэф.]],Таблица2[[#This Row],[Высота коэф.]])) -> 0.4 | V3: =IF(Таблица2[[#This Row],[Тип]]="произв",IF(Таблица2[[#This Row],[Капитальность]]<0.33,"произв класс 4",IF(Таблица2[[#This Row],[Капитальность]]<0.55,"произв класс 3",IF(Таблица2[[#This Row],[Капитальность]]<0.77,"произв класс 2","произв класс 1"))),IF(Таблица2[[#This Row],[Тип]]="гражд",IF(Таблица2[[#This Row],[Капитальность]]<0.33,"гражд класс 4",IF(Таблица2[[#This Row],[Капитальность]]<0.55,"гражд класс 3",IF(Таблица2[[#This Row],[Капитальность]]<0.77,"гражд класс 2","гражд класс 1"))),"прочие")) -> произв класс 3 | W3: =Таблица2[[#This Row],[Площадь, м2]]*Таблица2[[#This Row],[Капитальность]] -> 3792.84 | X3: =IF(AB3<4%,5,IF(AB3<9%,4.5,IF(AB3<14%,4,IF(AB3<24%,3.5,IF(AB3<40%,3,IF(AB3<60%,2.5,IF(AB3<80%,2,1))))))) -> 5 | Y3: =X3*Таблица2[[#This Row],[Площадь, м2]] -> 47410.5 | Z3: =Y3*Таблица2[[#This Row],[Капитальность]] -> 18964.2 | AB3: 0.01
A4: Объект оценки 1 | B4: 10520 | C4: Нежилое помещение | D4: произв | E4: 5-8 м. | F4: {=_xlfn.XLOOKUP(1,(Таблица2[[#This Row],[Тип]]=коэф_произв[Тип])*(Таблица2[[#This Row],[Высота]]=коэф_произв[Значение])*('Таблица объектов'!E$1=коэф_произв[Характеристика]),коэф_произв[Коэффициент],"",0)} -> 0.8 | G4: Нет | H4: {=_xlfn.XLOOKUP(1,(Таблица2[[#This Row],[Тип]]=коэф_произв[Тип])*(Таблица2[[#This Row],[Наличие / Возможность кран-балки]]=коэф_произв[Значение])*('Таблица объектов'!G$1=коэф_произв[Характеристика]),коэф_произв[Коэффициент],"",0)} -> 0.9 | I4: Блочные бескаркасные или металлокаркасные холодные | J4: {=_xlfn.XLOOKUP(1,(Таблица2[[#This Row],[Тип]]=коэф_произв[Тип])*(Таблица2[[#This Row],[Конструкция]]=коэф_произв[Значение])*('Таблица объектов'!I$1=коэф_произв[Характеристика]),коэф_произв[Коэффициент],"",0)} -> 0.5 | K4: Усиленные для техники или специальные | L4: {=_xlfn.XLOOKUP(1,(Таблица2[[#This Row],[Тип]]=коэф_произв[Тип])*(Таблица2[[#This Row],[Полы]]=коэф_произв[Значение])*('Таблица объектов'!K$1=коэф_произв[Характеристика]),коэф_произв[Коэффициент],"",0)} -> 1 | M4: Отсутствует или минимальное (минимальная разводка освещения, водопровода) | N4: {=_xlfn.XLOOKUP(1,(Таблица2[[#This Row],[Тип]]=коэф_произв[Тип])*(Таблица2[[#This Row],[Инженерное оснащение]]=коэф_произв[Значение])*('Таблица объектов'!M$1=коэф_произв[Характеристика]),коэф_произв[Коэффициент],"",0)} -> 0.8 | P4: {=_xlfn.XLOOKUP(1,(Таблица2[[#This Row],[Тип]]=коэф_произв[Тип])*(Таблица2[[#This Row],[Архитектура]]=коэф_произв[Значение])*('Таблица объектов'!O$1=коэф_произв[Характеристика]),коэф_произв[Коэффициент],"",0)} | R4: {=_xlfn.XLOOKUP(1,(Таблица2[[#This Row],[Тип]]=коэф_произв[Тип])*(Таблица2[[#This Row],[Планировка]]=коэф_произв[Значение])*('Таблица объектов'!Q$1=коэф_произв[Характеристика]),коэф_произв[Коэффициент],"",0)} | T4: {=_xlfn.XLOOKUP(1,(Таблица2[[#This Row],[Тип]]=коэф_произв[Тип])*(Таблица2[[#This Row],[Уровень отделки]]=коэф_произв[Значение])*('Таблица объектов'!S$1=коэф_произв[Характеристика]),коэф_произв[Коэффициент],"",0)} | U4: =IF(Таблица2[[#This Row],[Тип]]="прочие",0.05,PRODUCT(Таблица2[[#This Row],[Уровень отделки коэф.]],Таблица2[[#This Row],[Планировка коэф.]],Таблица2[[#This Row],[Архитектура коэф.]],Таблица2[[#This Row],[Инженерное оснащение коэф.]],Таблица2[[#This Row],[Полы коэф.]],Таблица2[[#This Row],[Конструкция коэф.]],Таблица2[[#This Row],[Наличие / Возможность кран-балки коэф.]],Таблица2[[#This Row],[Высота коэф.]])) -> 0.288 | V4: =IF(Таблица2[[#This Row],[Тип]]="произв",IF(Таблица2[[#This Row],[Капитальность]]<0.33,"произв класс 4",IF(Таблица2[[#This Row],[Капитальность]]<0.55,"произв класс 3",IF(Таблица2[[#This Row],[Капитальность]]<0.77,"произв класс 2","произв класс 1"))),IF(Таблица2[[#This Row],[Тип]]="гражд",IF(Таблица2[[#This Row],[Капитальность]]<0.33,"гражд класс 4",IF(Таблица2[[#This Row],[Капитальность]]<0.55,"гражд класс 3",IF(Таблица2[[#This Row],[Капитальность]]<0.77,"гражд класс 2","гражд класс 1"))),"прочие")) -> произв класс 4 | W4: =Таблица2[[#This Row],[Площадь, м2]]*Таблица2[[#This Row],[Капитальность]] -> 3029.76 | X4: =IF(AB4<4%,5,IF(AB4<9%,4.5,IF(AB4<14%,4,IF(AB4<24%,3.5,IF(AB4<40%,3,IF(AB4<60%,2.5,IF(AB4<80%,2,1))))))) -> 5 | Y4: =X4*Таблица2[[#This Row],[Площадь, м2]] -> 52600 | Z4: =Y4*Таблица2[[#This Row],[Капитальность]] -> 15148.8 | AB4: 0.01
A5: Объект оценки 1 | B5: 155.9 | C5: Нежилое помещение | D5: гражд | E5: До 2,6 м. | F5: {=_xlfn.XLOOKUP(1,(Таблица2[[#This Row],[Тип]]=коэф_произв[Тип])*(Таблица2[[#This Row],[Высота]]=коэф_произв[Значение])*('Таблица объектов'!E$1=коэф_произв[Характеристика]),коэф_произв[Коэффициент],"",0)} -> 0.6 | H5: {=_xlfn.XLOOKUP(1,(Таблица2[[#This Row],[Тип]]=коэф_произв[Тип])*(Таблица2[[#This Row],[Наличие / Возможность кран-балки]]=коэф_произв[Значение])*('Таблица объектов'!G$1=коэф_произв[Характеристика]),коэф_произв[Коэффициент],"",0)} | I5: Капитальная | J5: {=_xlfn.XLOOKUP(1,(Таблица2[[#This Row],[Тип]]=коэф_произв[Тип])*(Таблица2[[#This Row],[Конструкция]]=коэф_произв[Значение])*('Таблица объектов'!I$1=коэф_произв[Характеристика]),коэф_произв[Коэффициент],"",0)} -> 1 | L5: {=_xlfn.XLOOKUP(1,(Таблица2[[#This Row],[Тип]]=коэф_произв[Тип])*(Таблица2[[#This Row],[Полы]]=коэф_произв[Значение])*('Таблица объектов'!K$1=коэф_произв[Характеристика]),коэф_произв[Коэффициент],"",0)} | M5: Стандартное (по всем помещениям разводка освещения, водопровод, канализация) | N5: {=_xlfn.XLOOKUP(1,(Таблица2[[#This Row],[Тип]]=коэф_произв[Тип])*(Таблица2[[#This Row],[Инженерное оснащение]]=коэф_произв[Значение])*('Таблица объектов'!M$1=коэф_произв[Характеристика]),коэф_произв[Коэффициент],"",0)} -> 0.9 | O5: Устаревшая/ Современная | P5: {=_xlfn.XLOOKUP(1,(Таблица2[[#This Row],[Тип]]=коэф_произв[Тип])*(Таблица2[[#This Row],[Архитектура]]=коэф_произв[Значение])*('Таблица объектов'!O$1=коэф_произв[Характеристика]),коэф_произв[Коэффициент],"",0)} -> 0.9 | Q5: Смешанная | R5: {=_xlfn.XLOOKUP(1,(Таблица2[[#This Row],[Тип]]=коэф_произв[Тип])*(Таблица2[[#This Row],[Планировка]]=коэф_произв[Значение])*('Таблица объектов'!Q$1=коэф_произв[Характеристика]),коэф_произв[Коэффициент],"",0)} -> 0.95 | S5: Простая (потолки и стены оштукатурены, окрашены или отделаны дешевыми материалами (МДФ), полы линолеумные | T5: {=_xlfn.XLOOKUP(1,(Таблица2[[#This Row],[Тип]]=коэф_произв[Тип])*(Таблица2[[#This Row],[Уровень отделки]]=коэф_произв[Значение])*('Таблица объектов'!S$1=коэф_произв[Характеристика]),коэф_произв[Коэффициент],"",0)} -> 0.7 | U5: =IF(Таблица2[[#This Row],[Тип]]="прочие",0.05,PRODUCT(Таблица2[[#This Row],[Уровень отделки коэф.]],Таблица2[[#This Row],[Планировка коэф.]],Таблица2[[#This Row],[Архитектура коэф.]],Таблица2[[#This Row],[Инженерное оснащение коэф.]],Таблица2[[#This Row],[Полы коэф.]],Таблица2[[#This Row],[Конструкция коэф.]],Таблица2[[#This Row],[Наличие / Возможность кран-балки коэф.]],Таблица2[[#This Row],[Высота коэф.]])) -> 0.32319 | V5: =IF(Таблица2[[#This Row],[Тип]]="произв",IF(Таблица2[[#This Row],[Капитальность]]<0.33,"произв класс 4",IF(Таблица2[[#This Row],[Капитальность]]<0.55,"произв класс 3",IF(Таблица2[[#This Row],[Капитальность]]<0.77,"произв класс 2","произв класс 1"))),IF(Таблица2[[#This Row],[Тип]]="гражд",IF(Таблица2[[#This Row],[Капитальность]]<0.33,"гражд класс 4",IF(Таблица2[[#This Row],[Капитальность]]<0.55,"гражд класс 3",IF(Таблица2[[#This Row],[Капитальность]]<0.77,"гражд класс 2","гражд класс 1"))),"прочие")) -> гражд класс 4 | W5: =Таблица2[[#This Row],[Площадь, м2]]*Таблица2[[#This Row],[Капитальность]] -> 50.385321 | X5: =IF(AB5<4%,5,IF(AB5<9%,4.5,IF(AB5<14%,4,IF(AB5<24%,3.5,IF(AB5<40%,3,IF(AB5<60%,2.5,IF(AB5<80%,2,1))))))) -> 3 | Y5: =X5*Таблица2[[#This Row],[Площадь, м2]] -> 467.7 | Z5: =Y5*Таблица2[[#This Row],[Капитальность]] -> 151.15596 | AB5: 0.399
A6: Объект оценки 1 | B6: 189.4 | C6: Нежилое помещение | D6: произв | E6: 3-5 м. | F6: {=_xlfn.XLOOKUP(1,(Таблица2[[#This Row],[Тип]]=коэф_произв[Тип])*(Таблица2[[#This Row],[Высота]]=коэф_произв[Значение])*('Таблица объектов'!E$1=коэф_произв[Характеристика]),коэф_произв[Коэффициент],"",0)} -> 0.6 | G6: Нет | H6: {=_xlfn.XLOOKUP(1,(Таблица2[[#This Row],[Тип]]=коэф_произв[Тип])*(Таблица2[[#This Row],[Наличие / Возможность кран-балки]]=коэф_произв[Значение])*('Таблица объектов'!G$1=коэф_произв[Характеристика]),коэф_произв[Коэффициент],"",0)} -> 0.9 | I6: Блочные по железобетонному каркасу, утепленные | J6: {=_xlfn.XLOOKUP(1,(Таблица2[[#This Row],[Тип]]=коэф_произв[Тип])*(Таблица2[[#This Row],[Конструкция]]=коэф_произв[Значение])*('Таблица объектов'!I$1=коэф_произв[Характеристика]),коэф_произв[Коэффициент],"",0)} -> 1 | K6: Простые | L6: {=_xlfn.XLOOKUP(1,(Таблица2[[#This Row],[Тип]]=коэф_произв[Тип])*(Таблица2[[#This Row],[Полы]]=коэф_произв[Значение])*('Таблица объектов'!K$1=коэф_произв[Характеристика]),коэф_произв[Коэффициент],"",0)} -> 0.9 | M6: Стандартное (по всем помещениям разводка освещения, водопровод, канализация) | N6: {=_xlfn.XLOOKUP(1,(Таблица2[[#This Row],[Тип]]=коэф_произв[Тип])*(Таблица2[[#This Row],[Инженерное оснащение]]=коэф_произв[Значение])*('Таблица объектов'!M$1=коэф_произв[Характеристика]),коэф_произв[Коэффициент],"",0)} -> 0.9 | P6: {=_xlfn.XLOOKUP(1,(Таблица2[[#This Row],[Тип]]=коэф_произв[Тип])*(Таблица2[[#This Row],[Архитектура]]=коэф_произв[Значение])*('Таблица объектов'!O$1=коэф_произв[Характеристика]),коэф_произв[Коэффициент],"",0)} | R6: {=_xlfn.XLOOKUP(1,(Таблица2[[#This Row],[Тип]]=коэф_произв[Тип])*(Таблица2[[#This Row],[Планировка]]=коэф_произв[Значение])*('Таблица объектов'!Q$1=коэф_произв[Характеристика]),коэф_произв[Коэффициент],"",0)} | T6: {=_xlfn.XLOOKUP(1,(Таблица2[[#This Row],[Тип]]=коэф_произв[Тип])*(Таблица2[[#This Row],[Уровень отделки]]=коэф_произв[Значение])*('Таблица объектов'!S$1=коэф_произв[Характеристика]),коэф_произв[Коэффициент],"",0)} | U6: =IF(Таблица2[[#This Row],[Тип]]="прочие",0.05,PRODUCT(Таблица2[[#This Row],[Уровень отделки коэф.]],Таблица2[[#This Row],[Планировка коэф.]],Таблица2[[#This Row],[Архитектура коэф.]],Таблица2[[#This Row],[Инженерное оснащение коэф.]],Таблица2[[#This Row],[Полы коэф.]],Таблица2[[#This Row],[Конструкция коэф.]],Таблица2[[#This Row],[Наличие / Возможность кран-балки коэф.]],Таблица2[[#This Row],[Высота коэф.]])) -> 0.4374 | V6: =IF(Таблица2[[#This Row],[Тип]]="произв",IF(Таблица2[[#This Row],[Капитальность]]<0.33,"произв класс 4",IF(Таблица2[[#This Row],[Капитальность]]<0.55,"произв класс 3",IF(Таблица2[[#This Row],[Капитальность]]<0.77,"произв класс 2","произв класс 1"))),IF(Таблица2[[#This Row],[Тип]]="гражд",IF(Таблица2[[#This Row],[Капитальность]]<0.33,"гражд класс 4",IF(Таблица2[[#This Row],[Капитальность]]<0.55,"гражд класс 3",IF(Таблица2[[#This Row],[Капитальность]]<0.77,"гражд класс 2","гражд класс 1"))),"прочие")) -> произв класс 3 | W6: =Таблица2[[#This Row],[Площадь, м2]]*Таблица2[[#This Row],[Капитальность]] -> 82.84356 | X6: =IF(AB6<4%,5,IF(AB6<9%,4.5,IF(AB6<14%,4,IF(AB6<24%,3.5,IF(AB6<40%,3,IF(AB6<60%,2.5,IF(AB6<80%,2,1))))))) -> 3 | Y6: =X6*Таблица2[[#This Row],[Площадь, м2]] -> 568.2 | Z6: =Y6*Таблица2[[#This Row],[Капитальность]] -> 248.53068 | AB6: 0.369
A7: Объект оценки 2 | B7: 4736.5 | C7: Нежилое помещение (склады) | D7: произв | E7: Более 8 м. (условно - 10 м в среднем) | F7: {=_xlfn.XLOOKUP(1,(Таблица2[[#This Row],[Тип]]=коэф_произв[Тип])*(Таблица2[[#This Row],[Высота]]=коэф_произв[Значение])*('Таблица объектов'!E$1=коэф_произв[Характеристика]),коэф_произв[Коэффициент],"",0)} -> 1 | G7: Да | H7: {=_xlfn.XLOOKUP(1,(Таблица2[[#This Row],[Тип]]=коэф_произв[Тип])*(Таблица2[[#This Row],[Наличие / Возможность кран-балки]]=коэф_произв[Значение])*('Таблица объектов'!G$1=коэф_произв[Характеристика]),коэф_произв[Коэффициент],"",0)} -> 1 | I7: Блочные бескаркасные или металлокаркасные холодные | J7: {=_xlfn.XLOOKUP(1,(Таблица2[[#This Row],[Тип]]=коэф_произв[Тип])*(Таблица2[[#This Row],[Конструкция]]=коэф_произв[Значение])*('Таблица объектов'!I$1=коэф_произв[Характеристика]),коэф_произв[Коэффициент],"",0)} -> 0.5 | K7: Усиленные для техники или специальные | L7: {=_xlfn.XLOOKUP(1,(Таблица2[[#This Row],[Тип]]=коэф_произв[Тип])*(Таблица2[[#This Row],[Полы]]=коэф_произв[Значение])*('Таблица объектов'!K$1=коэф_произв[Характеристика]),коэф_произв[Коэффициент],"",0)} -> 1 | M7: Отсутствует или минимальное (минимальная разводка освещения, водопровода) | N7: {=_xlfn.XLOOKUP(1,(Таблица2[[#This Row],[Тип]]=коэф_произв[Тип])*(Таблица2[[#This Row],[Инженерное оснащение]]=коэф_произв[Значение])*('Таблица объектов'!M$1=коэф_произв[Характеристика]),коэф_произв[Коэффициент],"",0)} -> 0.8 | P7: {=_xlfn.XLOOKUP(1,(Таблица2[[#This Row],[Тип]]=коэф_произв[Тип])*(Таблица2[[#This Row],[Архитектура]]=коэф_произв[Значение])*('Таблица объектов'!O$1=коэф_произв[Характеристика]),коэф_произв[Коэффициент],"",0)} | R7: {=_xlfn.XLOOKUP(1,(Таблица2[[#This Row],[Тип]]=коэф_произв[Тип])*(Таблица2[[#This Row],[Планировка]]=коэф_произв[Значение])*('Таблица объектов'!Q$1=коэф_произв[Характеристика]),коэф_произв[Коэффициент],"",0)} | T7: {=_xlfn.XLOOKUP(1,(Таблица2[[#This Row],[Тип]]=коэф_произв[Тип])*(Таблица2[[#This Row],[Уровень отделки]]=коэф_произв[Значение])*('Таблица объектов'!S$1=коэф_произв[Характеристика]),коэф_произв[Коэффициент],"",0)} | U7: =IF(Таблица2[[#This Row],[Тип]]="прочие",0.05,PRODUCT(Таблица2[[#This Row],[Уровень отделки коэф.]],Таблица2[[#This Row],[Планировка коэф.]],Таблица2[[#This Row],[Архитектура коэф.]],Таблица2[[#This Row],[Инженерное оснащение коэф.]],Таблица2[[#This Row],[Полы коэф.]],Таблица2[[#This Row],[Конструкция коэф.]],Таблица2[[#This Row],[Наличие / Возможность кран-балки коэф.]],Таблица2[[#This Row],[Высота коэф.]])) -> 0.4 | V7: =IF(Таблица2[[#This Row],[Тип]]="произв",IF(Таблица2[[#This Row],[Капитальность]]<0.33,"произв класс 4",IF(Таблица2[[#This Row],[Капитальность]]<0.55,"произв класс 3",IF(Таблица2[[#This Row],[Капитальность]]<0.77,"произв класс 2","произв класс 1"))),IF(Таблица2[[#This Row],[Тип]]="гражд",IF(Таблица2[[#This Row],[Капитальность]]<0.33,"гражд класс 4",IF(Таблица2[[#This Row],[Капитальность]]<0.55,"гражд класс 3",IF(Таблица2[[#This Row],[Капитальность]]<0.77,"гражд класс 2","гражд класс 1"))),"прочие")) -> произв класс 3 | W7: =Таблица2[[#This Row],[Площадь, м2]]*Таблица2[[#This Row],[Капитальность]] -> 1894.6 | X7: =IF(AB7<4%,5,IF(AB7<9%,4.5,IF(AB7<14%,4,IF(AB7<24%,3.5,IF(AB7<40%,3,IF(AB7<60%,2.5,IF(AB7<80%,2,1))))))) -> 5 | Y7: =X7*Таблица2[[#This Row],[Площадь, м2]] -> 23682.5 | Z7: =Y7*Таблица2[[#This Row],[Капитальность]] -> 9473 | AB7: 0.005
A8: Объект оценки 2 | B8: 14304 | C8: Нежилое помещение с пристройко (склады) | D8: произв | E8: Более 8 м. (условно - 10 м в среднем) | F8: {=_xlfn.XLOOKUP(1,(Таблица2[[#This Row],[Тип]]=коэф_произв[Тип])*(Таблица2[[#This Row],[Высота]]=коэф_произв[Значение])*('Таблица объектов'!E$1=коэф_произв[Характеристика]),коэф_произв[Коэффициент],"",0)} -> 1 | G8: Да | H8: {=_xlfn.XLOOKUP(1,(Таблица2[[#This Row],[Тип]]=коэф_произв[Тип])*(Таблица2[[#This Row],[Наличие / Возможность кран-балки]]=коэф_произв[Значение])*('Таблица объектов'!G$1=коэф_произв[Характеристика]),коэф_произв[Коэффициент],"",0)} -> 1 | I8: Блочные бескаркасные или металлокаркасные холодные | J8: {=_xlfn.XLOOKUP(1,(Таблица2[[#This Row],[Тип]]=коэф_произв[Тип])*(Таблица2[[#This Row],[Конструкция]]=коэф_произв[Значение])*('Таблица объектов'!I$1=коэф_произв[Характеристика]),коэф_произв[Коэффициент],"",0)} -> 0.5 | K8: Усиленные для техники или специальные | L8: {=_xlfn.XLOOKUP(1,(Таблица2[[#This Row],[Тип]]=коэф_произв[Тип])*(Таблица2[[#This Row],[Полы]]=коэф_произв[Значение])*('Таблица объектов'!K$1=коэф_произв[Характеристика]),коэф_произв[Коэффициент],"",0)} -> 1 | M8: Отсутствует или минимальное (минимальная разводка освещения, водопровода) | N8: {=_xlfn.XLOOKUP(1,(Таблица2[[#This Row],[Тип]]=коэф_произв[Тип])*(Таблица2[[#This Row],[Инженерное оснащение]]=коэф_произв[Значение])*('Таблица объектов'!M$1=коэф_произв[Характеристика]),коэф_произв[Коэффициент],"",0)} -> 0.8 | P8: {=_xlfn.XLOOKUP(1,(Таблица2[[#This Row],[Тип]]=коэф_произв[Тип])*(Таблица2[[#This Row],[Архитектура]]=коэф_произв[Значение])*('Таблица объектов'!O$1=коэф_произв[Характеристика]),коэф_произв[Коэффициент],"",0)} | R8: {=_xlfn.XLOOKUP(1,(Таблица2[[#This Row],[Тип]]=коэф_произв[Тип])*(Таблица2[[#This Row],[Планировка]]=коэф_произв[Значение])*('Таблица объектов'!Q$1=коэф_произв[Характеристика]),коэф_произв[Коэффициент],"",0)} | T8: {=_xlfn.XLOOKUP(1,(Таблица2[[#This Row],[Тип]]=коэф_произв[Тип])*(Таблица2[[#This Row],[Уровень отделки]]=коэф_произв[Значение])*('Таблица объектов'!S$1=коэф_произв[Характеристика]),коэф_произв[Коэффициент],"",0)} | U8: =IF(Таблица2[[#This Row],[Тип]]="прочие",0.05,PRODUCT(Таблица2[[#This Row],[Уровень отделки коэф.]],Таблица2[[#This Row],[Планировка коэф.]],Таблица2[[#This Row],[Архитектура коэф.]],Таблица2[[#This Row],[Инженерное оснащение коэф.]],Таблица2[[#This Row],[Полы коэф.]],Таблица2[[#This Row],[Конструкция коэф.]],Таблица2[[#This Row],[Наличие / Возможность кран-балки коэф.]],Таблица2[[#This Row],[Высота коэф.]])) -> 0.4 | V8: =IF(Таблица2[[#This Row],[Тип]]="произв",IF(Таблица2[[#This Row],[Капитальность]]<0.33,"произв класс 4",IF(Таблица2[[#This Row],[Капитальность]]<0.55,"произв класс 3",IF(Таблица2[[#This Row],[Капитальность]]<0.77,"произв класс 2","произв класс 1"))),IF(Таблица2[[#This Row],[Тип]]="гражд",IF(Таблица2[[#This Row],[Капитальность]]<0.33,"гражд класс 4",IF(Таблица2[[#This Row],[Капитальность]]<0.55,"гражд класс 3",IF(Таблица2[[#This Row],[Капитальность]]<0.77,"гражд класс 2","гражд класс 1"))),"прочие")) -> произв класс 3 | W8: =Таблица2[[#This Row],[Площадь, м2]]*Таблица2[[#This Row],[Капитальность]] -> 5721.6 | X8: =IF(AB8<4%,5,IF(AB8<9%,4.5,IF(AB8<14%,4,IF(AB8<24%,3.5,IF(AB8<40%,3,IF(AB8<60%,2.5,IF(AB8<80%,2,1))))))) -> 5 | Y8: =X8*Таблица2[[#This Row],[Площадь, м2]] -> 71520 | Z8: =Y8*Таблица2[[#This Row],[Капитальность]] -> 28608 | AB8: 0.003
A9: Объект оценки 2 | B9: 949.5 | C9: Нежилое помещение с пристройко (склады) | D9: гражд | E9: 2,6-3,2 м. | F9: {=_xlfn.XLOOKUP(1,(Таблица2[[#This Row],[Тип]]=коэф_произв[Тип])*(Таблица2[[#This Row],[Высота]]=коэф_произв[Значение])*('Таблица объектов'!E$1=коэф_произв[Характеристика]),коэф_произв[Коэффициент],"",0)} -> 0.7 | H9: {=_xlfn.XLOOKUP(1,(Таблица2[[#This Row],[Тип]]=коэф_произв[Тип])*(Таблица2[[#This Row],[Наличие / Возможность кран-балки]]=коэф_произв[Значение])*('Таблица объектов'!G$1=коэф_произв[Характеристика]),коэф_произв[Коэффициент],"",0)} | I9: Капитальная | J9: {=_xlfn.XLOOKUP(1,(Таблица2[[#This Row],[Тип]]=коэф_произв[Тип])*(Таблица2[[#This Row],[Конструкция]]=коэф_произв[Значение])*('Таблица объектов'!I$1=коэф_произв[Характеристика]),коэф_произв[Коэффициент],"",0)} -> 1 | L9: {=_xlfn.XLOOKUP(1,(Таблица2[[#This Row],[Тип]]=коэф_произв[Тип])*(Таблица2[[#This Row],[Полы]]=коэф_произв[Значение])*('Таблица объектов'!K$1=коэф_произв[Характеристика]),коэф_произв[Коэффициент],"",0)} | M9: Стандартное (по всем помещениям разводка освещения, водопровод, канализация) | N9: {=_xlfn.XLOOKUP(1,(Таблица2[[#This Row],[Тип]]=коэф_произв[Тип])*(Таблица2[[#This Row],[Инженерное оснащение]]=коэф_произв[Значение])*('Таблица объектов'!M$1=коэф_произв[Характеристика]),коэф_произв[Коэффициент],"",0)} -> 0.9 | O9: Современная | P9: {=_xlfn.XLOOKUP(1,(Таблица2[[#This Row],[Тип]]=коэф_произв[Тип])*(Таблица2[[#This Row],[Архитектура]]=коэф_произв[Значение])*('Таблица объектов'!O$1=коэф_произв[Характеристика]),коэф_произв[Коэффициент],"",0)} -> 1 | Q9: Смешанная | R9: {=_xlfn.XLOOKUP(1,(Таблица2[[#This Row],[Тип]]=коэф_произв[Тип])*(Таблица2[[#This Row],[Планировка]]=коэф_произв[Значение])*('Таблица объектов'!Q$1=коэф_произв[Характеристика]),коэф_произв[Коэффициент],"",0)} -> 0.95 | S9: Стандартная (современная отделка с применением актуальных материалов) | T9: {=_xlfn.XLOOKUP(1,(Таблица2[[#This Row],[Тип]]=коэф_произв[Тип])*(Таблица2[[#This Row],[Уровень отделки]]=коэф_произв[Значение])*('Таблица объектов'!S$1=коэф_произв[Характеристика]),коэф_произв[Коэффициент],"",0)} -> 0.8 | U9: =IF(Таблица2[[#This Row],[Тип]]="прочие",0.05,PRODUCT(Таблица2[[#This Row],[Уровень отделки коэф.]],Таблица2[[#This Row],[Планировка коэф.]],Таблица2[[#This Row],[Архитектура коэф.]],Таблица2[[#This Row],[Инженерное оснащение коэф.]],Таблица2[[#This Row],[Полы коэф.]],Таблица2[[#This Row],[Конструкция коэф.]],Таблица2[[#This Row],[Наличие / Возможность кран-балки коэф.]],Таблица2[[#This Row],[Высота коэф.]])) -> 0.4788 | V9: =IF(Таблица2[[#This Row],[Тип]]="произв",IF(Таблица2[[#This Row],[Капитальность]]<0.33,"произв класс 4",IF(Таблица2[[#This Row],[Капитальность]]<0.55,"произв класс 3",IF(Таблица2[[#This Row],[Капитальность]]<0.77,"произв класс 2","произв класс 1"))),IF(Таблица2[[#This Row],[Тип]]="гражд",IF(Таблица2[[#This Row],[Капитальность]]<0.33,"гражд класс 4",IF(Таблица2[[#This Row],[Капитальность]]<0.55,"гражд класс 3",IF(Таблица2[[#This Row],[Капитальность]]<0.77,"гражд класс 2","гражд класс 1"))),"прочие")) -> гражд класс 3 | W9: =Таблица2[[#This Row],[Площадь, м2]]*Таблица2[[#This Row],[Капитальность]] -> 454.6206 | X9: =IF(AB9<4%,5,IF(AB9<9%,4.5,IF(AB9<14%,4,IF(AB9<24%,3.5,IF(AB9<40%,3,IF(AB9<60%,2.5,IF(AB9<80%,2,1))))))) -> 5 | Y9: =X9*Таблица2[[#This Row],[Площадь, м2]] -> 4747.5 | Z9: =Y9*Таблица2[[#This Row],[Капитальность]] -> 2273.103 | AB9: 0.001
A10: Объект оценки 3 | B10: 4393.4 | C10: Нежилое помещение швейный цех | D10: гражд | E10: 2,6-3,2 м. | F10: {=_xlfn.XLOOKUP(1,(Таблица2[[#This Row],[Тип]]=коэф_произв[Тип])*(Таблица2[[#This Row],[Высота]]=коэф_произв[Значение])*('Таблица объектов'!E$1=коэф_произв[Характеристика]),коэф_произв[Коэффициент],"",0)} -> 0.7 | H10: {=_xlfn.XLOOKUP(1,(Таблица2[[#This Row],[Тип]]=коэф_произв[Тип])*(Таблица2[[#This Row],[Наличие / Возможность кран-балки]]=коэф_произв[Значение])*('Таблица объектов'!G$1=коэф_произв[Характеристика]),коэф_произв[Коэффициент],"",0)} | I10: Капитальная | J10: {=_xlfn.XLOOKUP(1,(Таблица2[[#This Row],[Тип]]=коэф_произв[Тип])*(Таблица2[[#This Row],[Конструкция]]=коэф_произв[Значение])*('Таблица объектов'!I$1=коэф_произв[Характеристика]),коэф_произв[Коэффициент],"",0)} -> 1 | L10: {=_xlfn.XLOOKUP(1,(Таблица2[[#This Row],[Тип]]=коэф_произв[Тип])*(Таблица2[[#This Row],[Полы]]=коэф_произв[Значение])*('Таблица объектов'!K$1=коэф_произв[Характеристика]),коэф_произв[Коэффициент],"",0)} | M10: Стандартное (по всем помещениям разводка освещения, водопровод, канализация) | N10: {=_xlfn.XLOOKUP(1,(Таблица2[[#This Row],[Тип]]=коэф_произв[Тип])*(Таблица2[[#This Row],[Инженерное оснащение]]=коэф_произв[Значение])*('Таблица объектов'!M$1=коэф_произв[Характеристика]),коэф_произв[Коэффициент],"",0)} -> 0.9 | O10: Устаревшая | P10: {=_xlfn.XLOOKUP(1,(Таблица2[[#This Row],[Тип]]=коэф_произв[Тип])*(Таблица2[[#This Row],[Архитектура]]=коэф_произв[Значение])*('Таблица объектов'!O$1=коэф_произв[Характеристика]),коэф_произв[Коэффициент],"",0)} -> 0.8 | Q10: Смешанная | R10: {=_xlfn.XLOOKUP(1,(Таблица2[[#This Row],[Тип]]=коэф_произв[Тип])*(Таблица2[[#This Row],[Планировка]]=коэф_произв[Значение])*('Таблица объектов'!Q$1=коэф_произв[Характеристика]),коэф_произв[Коэффициент],"",0)} -> 0.95 | S10: Простая (потолки и стены оштукатурены, окрашены или отделаны дешевыми материалами (МДФ), полы линолеумные | T10: {=_xlfn.XLOOKUP(1,(Таблица2[[#This Row],[Тип]]=коэф_произв[Тип])*(Таблица2[[#This Row],[Уровень отделки]]=коэф_произв[Значение])*('Таблица объектов'!S$1=коэф_произв[Характеристика]),коэф_произв[Коэффициент],"",0)} -> 0.7 | U10: =IF(Таблица2[[#This Row],[Тип]]="прочие",0.05,PRODUCT(Таблица2[[#This Row],[Уровень отделки коэф.]],Таблица2[[#This Row],[Планировка коэф.]],Таблица2[[#This Row],[Архитектура коэф.]],Таблица2[[#This Row],[Инженерное оснащение коэф.]],Таблица2[[#This Row],[Полы коэф.]],Таблица2[[#This Row],[Конструкция коэф.]],Таблица2[[#This Row],[Наличие / Возможность кран-балки коэф.]],Таблица2[[#This Row],[Высота коэф.]])) -> 0.33516 | V10: =IF(Таблица2[[#This Row],[Тип]]="произв",IF(Таблица2[[#This Row],[Капитальность]]<0.33,"произв класс 4",IF(Таблица2[[#This Row],[Капитальность]]<0.55,"произв класс 3",IF(Таблица2[[#This Row],[Капитальность]]<0.77,"произв класс 2","произв класс 1"))),IF(Таблица2[[#This Row],[Тип]]="гражд",IF(Таблица2[[#This Row],[Капитальность]]<0.33,"гражд класс 4",IF(Таблица2[[#This Row],[Капитальность]]<0.55,"гражд класс 3",IF(Таблица2[[#This Row],[Капитальность]]<0.77,"гражд класс 2","гражд класс 1"))),"прочие")) -> гражд класс 3 | W10: =Таблица2[[#This Row],[Площадь, м2]]*Таблица2[[#This Row],[Капитальность]] -> 1472.4919 | X10: =IF(AB10<4%,5,IF(AB10<9%,4.5,IF(AB10<14%,4,IF(AB10<24%,3.5,IF(AB10<40%,3,IF(AB10<60%,2.5,IF(AB10<80%,2,1))))))) -> 2.5 | Y10: =X10*Таблица2[[#This Row],[Площадь, м2]] -> 10983.5 | Z10: =Y10*Таблица2[[#This Row],[Капитальность]] -> 3681.2299 | AB10: 0.462
A11: Объект оценки 3 | B11: 11110.7 | C11: Нежилое помещение склад | D11: произв | E11: 5-8 м. | F11: {=_xlfn.XLOOKUP(1,(Таблица2[[#This Row],[Тип]]=коэф_произв[Тип])*(Таблица2[[#This Row],[Высота]]=коэф_произв[Значение])*('Таблица объектов'!E$1=коэф_произв[Характеристика]),коэф_произв[Коэффициент],"",0)} -> 0.8 | G11: Не установлено (по умолчанию) | H11: {=_xlfn.XLOOKUP(1,(Таблица2[[#This Row],[Тип]]=коэф_произв[Тип])*(Таблица2[[#This Row],[Наличие / Возможность кран-балки]]=коэф_произв[Значение])*('Таблица объектов'!G$1=коэф_произв[Характеристика]),коэф_произв[Коэффициент],"",0)} -> 0.95 | I11: Блочные по железобетонному каркасу, без утепления | J11: {=_xlfn.XLOOKUP(1,(Таблица2[[#This Row],[Тип]]=коэф_произв[Тип])*(Таблица2[[#This Row],[Конструкция]]=коэф_произв[Значение])*('Таблица объектов'!I$1=коэф_произв[Характеристика]),коэф_произв[Коэффициент],"",0)} -> 0.7 | K11: Простые | L11: {=_xlfn.XLOOKUP(1,(Таблица2[[#This Row],[Тип]]=коэф_произв[Тип])*(Таблица2[[#This Row],[Полы]]=коэф_произв[Значение])*('Таблица объектов'!K$1=коэф_произв[Характеристика]),коэф_произв[Коэффициент],"",0)} -> 0.9 | M11: Стандартное (по всем помещениям разводка освещения, водопровод, канализация) | N11: {=_xlfn.XLOOKUP(1,(Таблица2[[#This Row],[Тип]]=коэф_произв[Тип])*(Таблица2[[#This Row],[Инженерное оснащение]]=коэф_произв[Значение])*('Таблица объектов'!M$1=коэф_произв[Характеристика]),коэф_произв[Коэффициент],"",0)} -> 0.9 | P11: {=_xlfn.XLOOKUP(1,(Таблица2[[#This Row],[Тип]]=коэф_произв[Тип])*(Таблица2[[#This Row],[Архитектура]]=коэф_произв[Значение])*('Таблица объектов'!O$1=коэф_произв[Характеристика]),коэф_произв[Коэффициент],"",0)} | R11: {=_xlfn.XLOOKUP(1,(Таблица2[[#This Row],[Тип]]=коэф_произв[Тип])*(Таблица2[[#This Row],[Планировка]]=коэф_произв[Значение])*('Таблица объектов'!Q$1=коэф_произв[Характеристика]),коэф_произв[Коэффициент],"",0)} | T11: {=_xlfn.XLOOKUP(1,(Таблица2[[#This Row],[Тип]]=коэф_произв[Тип])*(Таблица2[[#This Row],[Уровень отделки]]=коэф_произв[Значение])*('Таблица объектов'!S$1=коэф_произв[Характеристика]),коэф_произв[Коэффициент],"",0)} | U11: =IF(Таблица2[[#This Row],[Тип]]="прочие",0.05,PRODUCT(Таблица2[[#This Row],[Уровень отделки коэф.]],Таблица2[[#This Row],[Планировка коэф.]],Таблица2[[#This Row],[Архитектура коэф.]],Таблица2[[#This Row],[Инженерное оснащение коэф.]],Таблица2[[#This Row],[Полы коэф.]],Таблица2[[#This Row],[Конструкция коэф.]],Таблица2[[#This Row],[Наличие / Возможность кран-балки коэф.]],Таблица2[[#This Row],[Высота коэф.]])) -> 0.43092 | V11: =IF(Таблица2[[#This Row],[Тип]]="произв",IF(Таблица2[[#This Row],[Капитальность]]<0.33,"произв класс 4",IF(Таблица2[[#This Row],[Капитальность]]<0.55,"произв класс 3",IF(Таблица2[[#This Row],[Капитальность]]<0.77,"произв класс 2","произв класс 1"))),IF(Таблица2[[#This Row],[Тип]]="гражд",IF(Таблица2[[#This Row],[Капитальность]]<0.33,"гражд класс 4",IF(Таблица2[[#This Row],[Капитальность]]<0.55,"гражд класс 3",IF(Таблица2[[#This Row],[Капитальность]]<0.77,"гражд класс 2","гражд класс 1"))),"прочие")) -> произв класс 3 | W11: =Таблица2[[#This Row],[Площадь, м2]]*Таблица2[[#This Row],[Капитальность]] -> 4787.8228 | X11: =IF(AB11<4%,5,IF(AB11<9%,4.5,IF(AB11<14%,4,IF(AB11<24%,3.5,IF(AB11<40%,3,IF(AB11<60%,2.5,IF(AB11<80%,2,1))))))) -> 2.5 | Y11: =X11*Таблица2[[#This Row],[Площадь, м2]] -> 27776.75 | Z11: =Y11*Таблица2[[#This Row],[Капитальность]] -> 11969.557 | AB11: 0.492
A12: Объект оценки 3 | B12: 41.6 | C12: Нежилое помещение (гараж) | D12: гражд | E12: До 2,6 м. | F12: {=_xlfn.XLOOKUP(1,(Таблица2[[#This Row],[Тип]]=коэф_произв[Тип])*(Таблица2[[#This Row],[Высота]]=коэф_произв[Значение])*('Таблица объектов'!E$1=коэф_произв[Характеристика]),коэф_произв[Коэффициент],"",0)} -> 0.6 | H12: {=_xlfn.XLOOKUP(1,(Таблица2[[#This Row],[Тип]]=коэф_произв[Тип])*(Таблица2[[#This Row],[Наличие / Возможность кран-балки]]=коэф_произв[Значение])*('Таблица объектов'!G$1=коэф_произв[Характеристика]),коэф_произв[Коэффициент],"",0)} | I12: Капитальная | J12: {=_xlfn.XLOOKUP(1,(Таблица2[[#This Row],[Тип]]=коэф_произв[Тип])*(Таблица2[[#This Row],[Конструкция]]=коэф_произв[Значение])*('Таблица объектов'!I$1=коэф_произв[Характеристика]),коэф_произв[Коэффициент],"",0)} -> 1 | L12: {=_xlfn.XLOOKUP(1,(Таблица2[[#This Row],[Тип]]=коэф_произв[Тип])*(Таблица2[[#This Row],[Полы]]=коэф_произв[Значение])*('Таблица объектов'!K$1=коэф_произв[Характеристика]),коэф_произв[Коэффициент],"",0)} | M12: Отсутствует или минимальное (минимальная разводка освещения, водопровода) | N12: {=_xlfn.XLOOKUP(1,(Таблица2[[#This Row],[Тип]]=коэф_произв[Тип])*(Таблица2[[#This Row],[Инженерное оснащение]]=коэф_произв[Значение])*('Таблица объектов'!M$1=коэф_произв[Характеристика]),коэф_произв[Коэффициент],"",0)} -> 0.8 | O12: Устаревшая | P12: {=_xlfn.XLOOKUP(1,(Таблица2[[#This Row],[Тип]]=коэф_произв[Тип])*(Таблица2[[#This Row],[Архитектура]]=коэф_произв[Значение])*('Таблица объектов'!O$1=коэф_произв[Характеристика]),коэф_произв[Коэффициент],"",0)} -> 0.8 | Q12: Свободная | R12: {=_xlfn.XLOOKUP(1,(Таблица2[[#This Row],[Тип]]=коэф_произв[Тип])*(Таблица2[[#This Row],[Планировка]]=коэф_произв[Значение])*('Таблица объектов'!Q$1=коэф_произв[Характеристика]),коэф_произв[Коэффициент],"",0)} -> 0.9 | S12: Без отделки (потолки не подшиты или не отделаны, стены неоштукатурены или неокрашены, полы без покрытий со стяжкой или без) | T12: {=_xlfn.XLOOKUP(1,(Таблица2[[#This Row],[Тип]]=коэф_произв[Тип])*(Таблица2[[#This Row],[Уровень отделки]]=коэф_произв[Значение])*('Таблица объектов'!S$1=коэф_произв[Характеристика]),коэф_произв[Коэффициент],"",0)} -> 0.5 | U12: =IF(Таблица2[[#This Row],[Тип]]="прочие",0.05,PRODUCT(Таблица2[[#This Row],[Уровень отделки коэф.]],Таблица2[[#This Row],[Планировка коэф.]],Таблица2[[#This Row],[Архитектура коэф.]],Таблица2[[#This Row],[Инженерное оснащение коэф.]],Таблица2[[#This Row],[Полы коэф.]],Таблица2[[#This Row],[Конструкция коэф.]],Таблица2[[#This Row],[Наличие / Возможность кран-балки коэф.]],Таблица2[[#This Row],[Высота коэф.]])) -> 0.1728 | V12: =IF(Таблица2[[#This Row],[Тип]]="произв",IF(Таблица2[[#This Row],[Капитальность]]<0.33,"произв класс 4",IF(Таблица2[[#This Row],[Капитальность]]<0.55,"произв класс 3",IF(Таблица2[[#This Row],[Капитальность]]<0.77,"произв класс 2","произв класс 1"))),IF(Таблица2[[#This Row],[Тип]]="гражд",IF(Таблица2[[#This Row],[Капитальность]]<0.33,"гражд класс 4",IF(Таблица2[[#This Row],[Капитальность]]<0.55,"гражд класс 3",IF(Таблица2[[#This Row],[Капитальность]]<0.77,"гражд класс 2","гражд класс 1"))),"прочие")) -> гражд класс 4 | W12: =Таблица2[[#This Row],[Площадь, м2]]*Таблица2[[#This Row],[Капитальность]] -> 7.18848 | X12: =IF(AB12<4%,5,IF(AB12<9%,4.5,IF(AB12<14%,4,IF(AB12<24%,3.5,IF(AB12<40%,3,IF(AB12<60%,2.5,IF(AB12<80%,2,1))))))) -> 2.5 | Y12: =X12*Таблица2[[#This Row],[Площадь, м2]] -> 104 | Z12: =Y12*Таблица2[[#This Row],[Капитальность]] -> 17.9712 | AB12: 0.555
A13: Объект оценки 3 | B13: 58.5 | C13: Нежилое помещение | D13: произв | E13: 3-5 м. | F13: {=_xlfn.XLOOKUP(1,(Таблица2[[#This Row],[Тип]]=коэф_произв[Тип])*(Таблица2[[#This Row],[Высота]]=коэф_произв[Значение])*('Таблица объектов'!E$1=коэф_произв[Характеристика]),коэф_произв[Коэффициент],"",0)} -> 0.6 | G13: Нет | H13: {=_xlfn.XLOOKUP(1,(Таблица2[[#This Row],[Тип]]=коэф_произв[Тип])*(Таблица2[[#This Row],[Наличие / Возможность кран-балки]]=коэф_произв[Значение])*('Таблица объектов'!G$1=коэф_произв[Характеристика]),коэф_произв[Коэффициент],"",0)} -> 0.9 | I13: Блочные по железобетонному каркасу, без утепления | J13: {=_xlfn.XLOOKUP(1,(Таблица2[[#This Row],[Тип]]=коэф_произв[Тип])*(Таблица2[[#This Row],[Конструкция]]=коэф_произв[Значение])*('Таблица объектов'!I$1=коэф_произв[Характеристика]),коэф_произв[Коэффициент],"",0)} -> 0.7 | K13: Простые | L13: {=_xlfn.XLOOKUP(1,(Таблица2[[#This Row],[Тип]]=коэф_произв[Тип])*(Таблица2[[#This Row],[Полы]]=коэф_произв[Значение])*('Таблица объектов'!K$1=коэф_произв[Характеристика]),коэф_произв[Коэффициент],"",0)} -> 0.9 | M13: Отсутствует или минимальное (минимальная разводка освещения, водопровода) | N13: {=_xlfn.XLOOKUP(1,(Таблица2[[#This Row],[Тип]]=коэф_произв[Тип])*(Таблица2[[#This Row],[Инженерное оснащение]]=коэф_произв[Значение])*('Таблица объектов'!M$1=коэф_произв[Характеристика]),коэф_произв[Коэффициент],"",0)} -> 0.8 | P13: {=_xlfn.XLOOKUP(1,(Таблица2[[#This Row],[Тип]]=коэф_произв[Тип])*(Таблица2[[#This Row],[Архитектура]]=коэф_произв[Значение])*('Таблица объектов'!O$1=коэф_произв[Характеристика]),коэф_произв[Коэффициент],"",0)} | R13: {=_xlfn.XLOOKUP(1,(Таблица2[[#This Row],[Тип]]=коэф_произв[Тип])*(Таблица2[[#This Row],[Планировка]]=коэф_произв[Значение])*('Таблица объектов'!Q$1=коэф_произв[Характеристика]),коэф_произв[Коэффициент],"",0)} | T13: {=_xlfn.XLOOKUP(1,(Таблица2[[#This Row],[Тип]]=коэф_произв[Тип])*(Таблица2[[#This Row],[Уровень отделки]]=коэф_произв[Значение])*('Таблица объектов'!S$1=коэф_произв[Характеристика]),коэф_произв[Коэффициент],"",0)} | U13: =IF(Таблица2[[#This Row],[Тип]]="прочие",0.05,PRODUCT(Таблица2[[#This Row],[Уровень отделки коэф.]],Таблица2[[#This Row],[Планировка коэф.]],Таблица2[[#This Row],[Архитектура коэф.]],Таблица2[[#This Row],[Инженерное оснащение коэф.]],Таблица2[[#This Row],[Полы коэф.]],Таблица2[[#This Row],[Конструкция коэф.]],Таблица2[[#This Row],[Наличие / Возможность кран-балки коэф.]],Таблица2[[#This Row],[Высота коэф.]])) -> 0.27216 | V13: =IF(Таблица2[[#This Row],[Тип]]="произв",IF(Таблица2[[#This Row],[Капитальность]]<0.33,"произв класс 4",IF(Таблица2[[#This Row],[Капитальность]]<0.55,"произв класс 3",IF(Таблица2[[#This Row],[Капитальность]]<0.77,"произв класс 2","произв класс 1"))),IF(Таблица2[[#This Row],[Тип]]="гражд",IF(Таблица2[[#This Row],[Капитальность]]<0.33,"гражд класс 4",IF(Таблица2[[#This Row],[Капитальность]]<0.55,"гражд класс 3",IF(Таблица2[[#This Row],[Капитальность]]<0.77,"гражд класс 2","гражд класс 1"))),"прочие")) -> произв класс 4 | W13: =Таблица2[[#This Row],[Площадь, м2]]*Таблица2[[#This Row],[Капитальность]] -> 15.92136 | X13: =IF(AB13<4%,5,IF(AB13<9%,4.5,IF(AB13<14%,4,IF(AB13<24%,3.5,IF(AB13<40%,3,IF(AB13<60%,2.5,IF(AB13<80%,2,1))))))) -> 2.5 | Y13: =X13*Таблица2[[#This Row],[Площадь, м2]] -> 146.25 | Z13: =Y13*Таблица2[[#This Row],[Капитальность]] -> 39.8034 | AB13: 0.5
A14: Объект оценки 3 | B14: 130.9 | C14: Нежилое помещение | D14: гражд | E14: 2,6-3,2 м. | F14: {=_xlfn.XLOOKUP(1,(Таблица2[[#This Row],[Тип]]=коэф_произв[Тип])*(Таблица2[[#This Row],[Высота]]=коэф_произв[Значение])*('Таблица объектов'!E$1=коэф_произв[Характеристика]),коэф_произв[Коэффициент],"",0)} -> 0.7 | H14: {=_xlfn.XLOOKUP(1,(Таблица2[[#This Row],[Тип]]=коэф_произв[Тип])*(Таблица2[[#This Row],[Наличие / Возможность кран-балки]]=коэф_произв[Значение])*('Таблица объектов'!G$1=коэф_произв[Характеристика]),коэф_произв[Коэффициент],"",0)} | I14: Капитальная | J14: {=_xlfn.XLOOKUP(1,(Таблица2[[#This Row],[Тип]]=коэф_произв[Тип])*(Таблица2[[#This Row],[Конструкция]]=коэф_произв[Значение])*('Таблица объектов'!I$1=коэф_произв[Характеристика]),коэф_произв[Коэффициент],"",0)} -> 1 | L14: {=_xlfn.XLOOKUP(1,(Таблица2[[#This Row],[Тип]]=коэф_произв[Тип])*(Таблица2[[#This Row],[Полы]]=коэф_произв[Значение])*('Таблица объектов'!K$1=коэф_произв[Характеристика]),коэф_произв[Коэффициент],"",0)} | M14: Стандартное (по всем помещениям разводка освещения, водопровод, канализация) | N14: {=_xlfn.XLOOKUP(1,(Таблица2[[#This Row],[Тип]]=коэф_произв[Тип])*(Таблица2[[#This Row],[Инженерное оснащение]]=коэф_произв[Значение])*('Таблица объектов'!M$1=коэф_произв[Характеристика]),коэф_произв[Коэффициент],"",0)} -> 0.9 | O14: Устаревшая | P14: {=_xlfn.XLOOKUP(1,(Таблица2[[#This Row],[Тип]]=коэф_произв[Тип])*(Таблица2[[#This Row],[Архитектура]]=коэф_произв[Значение])*('Таблица объектов'!O$1=коэф_произв[Характеристика]),коэф_произв[Коэффициент],"",0)} -> 0.8 | Q14: Смешанная | R14: {=_xlfn.XLOOKUP(1,(Таблица2[[#This Row],[Тип]]=коэф_произв[Тип])*(Таблица2[[#This Row],[Планировка]]=коэф_произв[Значение])*('Таблица объектов'!Q$1=коэф_произв[Характеристика]),коэф_произв[Коэффициент],"",0)} -> 0.95 | S14: Простая (потолки и стены оштукатурены, окрашены или отделаны дешевыми материалами (МДФ), полы линолеумные | T14: {=_xlfn.XLOOKUP(1,(Таблица2[[#This Row],[Тип]]=коэф_произв[Тип])*(Таблица2[[#This Row],[Уровень отделки]]=коэф_произв[Значение])*('Таблица объектов'!S$1=коэф_произв[Характеристика]),коэф_произв[Коэффициент],"",0)} -> 0.7 | U14: =IF(Таблица2[[#This Row],[Тип]]="прочие",0.05,PRODUCT(Таблица2[[#This Row],[Уровень отделки коэф.]],Таблица2[[#This Row],[Планировка коэф.]],Таблица2[[#This Row],[Архитектура коэф.]],Таблица2[[#This Row],[Инженерное оснащение коэф.]],Таблица2[[#This Row],[Полы коэф.]],Таблица2[[#This Row],[Конструкция коэф.]],Таблица2[[#This Row],[Наличие / Возможность кран-балки коэф.]],Таблица2[[#This Row],[Высота коэф.]])) -> 0.33516 | V14: =IF(Таблица2[[#This Row],[Тип]]="произв",IF(Таблица2[[#This Row],[Капитальность]]<0.33,"произв класс 4",IF(Таблица2[[#This Row],[Капитальность]]<0.55,"произв класс 3",IF(Таблица2[[#This Row],[Капитальность]]<0.77,"произв класс 2","произв класс 1"))),IF(Таблица2[[#This Row],[Тип]]="гражд",IF(Таблица2[[#This Row],[Капитальность]]<0.33,"гражд класс 4",IF(Таблица2[[#This Row],[Капитальность]]<0.55,"гражд класс 3",IF(Таблица2[[#This Row],[Капитальность]]<0.77,"гражд класс 2","гражд класс 1"))),"прочие")) -> гражд класс 3 | W14: =Таблица2[[#This Row],[Площадь, м2]]*Таблица2[[#This Row],[Капитальность]] -> 43.872444 | X14: =IF(AB14<4%,5,IF(AB14<9%,4.5,IF(AB14<14%,4,IF(AB14<24%,3.5,IF(AB14<40%,3,IF(AB14<60%,2.5,IF(AB14<80%,2,1))))))) -> 2.5 | Y14: =X14*Таблица2[[#This Row],[Площадь, м2]] -> 327.25 | Z14: =Y14*Таблица2[[#This Row],[Капитальность]] -> 109.68111 | AB14: 0.427
A15: Объект оценки 3 | B15: 18.19 | C15: Дополнительная пристройка | D15: гражд | E15: 2,6-3,2 м. | F15: {=_xlfn.XLOOKUP(1,(Таблица2[[#This Row],[Тип]]=коэф_произв[Тип])*(Таблица2[[#This Row],[Высота]]=коэф_произв[Значение])*('Таблица объектов'!E$1=коэф_произв[Характеристика]),коэф_произв[Коэффициент],"",0)} -> 0.7 | H15: {=_xlfn.XLOOKUP(1,(Таблица2[[#This Row],[Тип]]=коэф_произв[Тип])*(Таблица2[[#This Row],[Наличие / Возможность кран-балки]]=коэф_произв[Значение])*('Таблица объектов'!G$1=коэф_произв[Характеристика]),коэф_произв[Коэффициент],"",0)} | I15: Смешанная | J15: {=_xlfn.XLOOKUP(1,(Таблица2[[#This Row],[Тип]]=коэф_произв[Тип])*(Таблица2[[#This Row],[Конструкция]]=коэф_произв[Значение])*('Таблица объектов'!I$1=коэф_произв[Характеристика]),коэф_произв[Коэффициент],"",0)} -> 0.9 | L15: {=_xlfn.XLOOKUP(1,(Таблица2[[#This Row],[Тип]]=коэф_произв[Тип])*(Таблица2[[#This Row],[Полы]]=коэф_произв[Значение])*('Таблица объектов'!K$1=коэф_произв[Характеристика]),коэф_произв[Коэффициент],"",0)} | M15: Отсутствует или минимальное (минимальная разводка освещения, водопровода) | N15: {=_xlfn.XLOOKUP(1,(Таблица2[[#This Row],[Тип]]=коэф_произв[Тип])*(Таблица2[[#This Row],[Инженерное оснащение]]=коэф_произв[Значение])*('Таблица объектов'!M$1=коэф_произв[Характеристика]),коэф_произв[Коэффициент],"",0)} -> 0.8 | O15: Устаревшая | P15: {=_xlfn.XLOOKUP(1,(Таблица2[[#This Row],[Тип]]=коэф_произв[Тип])*(Таблица2[[#This Row],[Архитектура]]=коэф_произв[Значение])*('Таблица объектов'!O$1=коэф_произв[Характеристика]),коэф_произв[Коэффициент],"",0)} -> 0.8 | Q15: Смешанная | R15: {=_xlfn.XLOOKUP(1,(Таблица2[[#This Row],[Тип]]=коэф_произв[Тип])*(Таблица2[[#This Row],[Планировка]]=коэф_произв[Значение])*('Таблица объектов'!Q$1=коэф_произв[Характеристика]),коэф_произв[Коэффициент],"",0)} -> 0.95 | S15: Без отделки (потолки не подшиты или не отделаны, стены неоштукатурены или неокрашены, полы без покрытий со стяжкой или без) | T15: {=_xlfn.XLOOKUP(1,(Таблица2[[#This Row],[Тип]]=коэф_произв[Тип])*(Таблица2[[#This Row],[Уровень отделки]]=коэф_произв[Значение])*('Таблица объектов'!S$1=коэф_произв[Характеристика]),коэф_произв[Коэффициент],"",0)} -> 0.5 | U15: =IF(Таблица2[[#This Row],[Тип]]="прочие",0.05,PRODUCT(Таблица2[[#This Row],[Уровень отделки коэф.]],Таблица2[[#This Row],[Планировка коэф.]],Таблица2[[#This Row],[Архитектура коэф.]],Таблица2[[#This Row],[Инженерное оснащение коэф.]],Таблица2[[#This Row],[Полы коэф.]],Таблица2[[#This Row],[Конструкция коэф.]],Таблица2[[#This Row],[Наличие / Возможность кран-балки коэф.]],Таблица2[[#This Row],[Высота коэф.]])) -> 0.19152 | V15: =IF(Таблица2[[#This Row],[Тип]]="произв",IF(Таблица2[[#This Row],[Капитальность]]<0.33,"произв класс 4",IF(Таблица2[[#This Row],[Капитальность]]<0.55,"произв класс 3",IF(Таблица2[[#This Row],[Капитальность]]<0.77,"произв класс 2","произв класс 1"))),IF(Таблица2[[#This Row],[Тип]]="гражд",IF(Таблица2[[#This Row],[Капитальность]]<0.33,"гражд класс 4",IF(Таблица2[[#This Row],[Капитальность]]<0.55,"гражд класс 3",IF(Таблица2[[#This Row],[Капитальность]]<0.77,"гражд класс 2","гражд класс 1"))),"прочие")) -> гражд класс 4 | W15: =Таблица2[[#This Row],[Площадь, м2]]*Таблица2[[#This Row],[Капитальность]] -> 3.4837488 | X15: =IF(AB15<4%,5,IF(AB15<9%,4.5,IF(AB15<14%,4,IF(AB15<24%,3.5,IF(AB15<40%,3,IF(AB15<60%,2.5,IF(AB15<80%,2,1))))))) -> 2.5 | Y15: =X15*Таблица2[[#This Row],[Площадь, м2]] -> 45.475 | Z15: =Y15*Таблица2[[#This Row],[Капитальность]] -> 8.709372 | AB15: 0.427
A16: Объект оценки 3 | B16: 289.3 | C16: Нежилое помещение | D16: произв | E16: 5-8 м. | F16: {=_xlfn.XLOOKUP(1,(Таблица2[[#This Row],[Тип]]=коэф_произв[Тип])*(Таблица2[[#This Row],[Высота]]=коэф_произв[Значение])*('Таблица объектов'!E$1=коэф_произв[Характеристика]),коэф_произв[Коэффициент],"",0)} -> 0.8 | G16: Не установлено (по умолчанию) | H16: {=_xlfn.XLOOKUP(1,(Таблица2[[#This Row],[Тип]]=коэф_произв[Тип])*(Таблица2[[#This Row],[Наличие / Возможность кран-балки]]=коэф_произв[Значение])*('Таблица объектов'!G$1=коэф_произв[Характеристика]),коэф_произв[Коэффициент],"",0)} -> 0.95 | I16: Блочные по железобетонному каркасу, без утепления | J16: {=_xlfn.XLOOKUP(1,(Таблица2[[#This Row],[Тип]]=коэф_произв[Тип])*(Таблица2[[#This Row],[Конструкция]]=коэф_произв[Значение])*('Таблица объектов'!I$1=коэф_произв[Характеристика]),коэф_произв[Коэффициент],"",0)} -> 0.7 | K16: Простые | L16: {=_xlfn.XLOOKUP(1,(Таблица2[[#This Row],[Тип]]=коэф_произв[Тип])*(Таблица2[[#This Row],[Полы]]=коэф_произв[Значение])*('Таблица объектов'!K$1=коэф_произв[Характеристика]),коэф_произв[Коэффициент],"",0)} -> 0.9 | M16: Отсутствует или минимальное (минимальная разводка освещения, водопровода) | N16: {=_xlfn.XLOOKUP(1,(Таблица2[[#This Row],[Тип]]=коэф_произв[Тип])*(Таблица2[[#This Row],[Инженерное оснащение]]=коэф_произв[Значение])*('Таблица объектов'!M$1=коэф_произв[Характеристика]),коэф_произв[Коэффициент],"",0)} -> 0.8 | P16: {=_xlfn.XLOOKUP(1,(Таблица2[[#This Row],[Тип]]=коэф_произв[Тип])*(Таблица2[[#This Row],[Архитектура]]=коэф_произв[Значение])*('Таблица объектов'!O$1=коэф_произв[Характеристика]),коэф_произв[Коэффициент],"",0)} | R16: {=_xlfn.XLOOKUP(1,(Таблица2[[#This Row],[Тип]]=коэф_произв[Тип])*(Таблица2[[#This Row],[Планировка]]=коэф_произв[Значение])*('Таблица объектов'!Q$1=коэф_произв[Характеристика]),коэф_произв[Коэффициент],"",0)} | T16: {=_xlfn.XLOOKUP(1,(Таблица2[[#This Row],[Тип]]=коэф_произв[Тип])*(Таблица2[[#This Row],[Уровень отделки]]=коэф_произв[Значение])*('Таблица объектов'!S$1=коэф_произв[Характеристика]),коэф_произв[Коэффициент],"",0)} | U16: =IF(Таблица2[[#This Row],[Тип]]="прочие",0.05,PRODUCT(Таблица2[[#This Row],[Уровень отделки коэф.]],Таблица2[[#This Row],[Планировка коэф.]],Таблица2[[#This Row],[Архитектура коэф.]],Таблица2[[#This Row],[Инженерное оснащение коэф.]],Таблица2[[#This Row],[Полы коэф.]],Таблица2[[#This Row],[Конструкция коэф.]],Таблица2[[#This Row],[Наличие / Возможность кран-балки коэф.]],Таблица2[[#This Row],[Высота коэф.]])) -> 0.38304 | V16: =IF(Таблица2[[#This Row],[Тип]]="произв",IF(Таблица2[[#This Row],[Капитальность]]<0.33,"произв класс 4",IF(Таблица2[[#This Row],[Капитальность]]<0.55,"произв класс 3",IF(Таблица2[[#This Row],[Капитальность]]<0.77,"произв класс 2","произв класс 1"))),IF(Таблица2[[#This Row],[Тип]]="гражд",IF(Таблица2[[#This Row],[Капитальность]]<0.33,"гражд класс 4",IF(Таблица2[[#This Row],[Капитальность]]<0.55,"гражд класс 3",IF(Таблица2[[#This Row],[Капитальность]]<0.77,"гражд класс 2","гражд класс 1"))),"прочие")) -> произв класс 3 | W16: =Таблица2[[#This Row],[Площадь, м2]]*Таблица2[[#This Row],[Капитальность]] -> 110.81347 | X16: =IF(AB16<4%,5,IF(AB16<9%,4.5,IF(AB16<14%,4,IF(AB16<24%,3.5,IF(AB16<40%,3,IF(AB16<60%,2.5,IF(AB16<80%,2,1))))))) -> 2.5 | Y16: =X16*Таблица2[[#This Row],[Площадь, м2]] -> 723.25 | Z16: =Y16*Таблица2[[#This Row],[Капитальность]] -> 277.03368 | AB16: 0.465
A17: Объект оценки 3 | B17: 13.775 | C17: Навес | D17: прочие | F17: {=_xlfn.XLOOKUP(1,(Таблица2[[#This Row],[Тип]]=коэф_произв[Тип])*(Таблица2[[#This Row],[Высота]]=коэф_произв[Значение])*('Таблица объектов'!E$1=коэф_произв[Характеристика]),коэф_произв[Коэффициент],"",0)} | H17: {=_xlfn.XLOOKUP(1,(Таблица2[[#This Row],[Тип]]=коэф_произв[Тип])*(Таблица2[[#This Row],[Наличие / Возможность кран-балки]]=коэф_произв[Значение])*('Таблица объектов'!G$1=коэф_произв[Характеристика]),коэф_произв[Коэффициент],"",0)} | J17: {=_xlfn.XLOOKUP(1,(Таблица2[[#This Row],[Тип]]=коэф_произв[Тип])*(Таблица2[[#This Row],[Конструкция]]=коэф_произв[Значение])*('Таблица объектов'!I$1=коэф_произв[Характеристика]),коэф_произв[Коэффициент],"",0)} | L17: {=_xlfn.XLOOKUP(1,(Таблица2[[#This Row],[Тип]]=коэф_произв[Тип])*(Таблица2[[#This Row],[Полы]]=коэф_произв[Значение])*('Таблица объектов'!K$1=коэф_произв[Характеристика]),коэф_произв[Коэффициент],"",0)} | N17: {=_xlfn.XLOOKUP(1,(Таблица2[[#This Row],[Тип]]=коэф_произв[Тип])*(Таблица2[[#This Row],[Инженерное оснащение]]=коэф_произв[Значение])*('Таблица объектов'!M$1=коэф_произв[Характеристика]),коэф_произв[Коэффициент],"",0)} | P17: {=_xlfn.XLOOKUP(1,(Таблица2[[#This Row],[Тип]]=коэф_произв[Тип])*(Таблица2[[#This Row],[Архитектура]]=коэф_произв[Значение])*('Таблица объектов'!O$1=коэф_произв[Характеристика]),коэф_произв[Коэффициент],"",0)} | R17: {=_xlfn.XLOOKUP(1,(Таблица2[[#This Row],[Тип]]=коэф_произв[Тип])*(Таблица2[[#This Row],[Планировка]]=коэф_произв[Значение])*('Таблица объектов'!Q$1=коэф_произв[Характеристика]),коэф_произв[Коэффициент],"",0)} | T17: {=_xlfn.XLOOKUP(1,(Таблица2[[#This Row],[Тип]]=коэф_произв[Тип])*(Таблица2[[#This Row],[Уровень отделки]]=коэф_произв[Значение])*('Таблица объектов'!S$1=коэф_произв[Характеристика]),коэф_произв[Коэффициент],"",0)} | U17: =IF(Таблица2[[#This Row],[Тип]]="прочие",0.05,PRODUCT(Таблица2[[#This Row],[Уровень отделки коэф.]],Таблица2[[#This Row],[Планировка коэф.]],Таблица2[[#This Row],[Архитектура коэф.]],Таблица2[[#This Row],[Инженерное оснащение коэф.]],Таблица2[[#This Row],[Полы коэф.]],Таблица2[[#This Row],[Конструкция коэф.]],Таблица2[[#This Row],[Наличие / Возможность кран-балки коэф.]],Таблица2[[#This Row],[Высота коэф.]])) -> 0.05 | V17: =IF(Таблица2[[#This Row],[Тип]]="произв",IF(Таблица2[[#This Row],[Капитальность]]<0.33,"произв класс 4",IF(Таблица2[[#This Row],[Капитальность]]<0.55,"произв класс 3",IF(Таблица2[[#This Row],[Капитальность]]<0.77,"произв класс 2","произв класс 1"))),IF(Таблица2[[#This Row],[Тип]]="гражд",IF(Таблица2[[#This Row],[Капитальность]]<0.33,"гражд класс 4",IF(Таблица2[[#This Row],[Капитальность]]<0.55,"гражд класс 3",IF(Таблица2[[#This Row],[Капитальность]]<0.77,"гражд класс 2","гражд класс 1"))),"прочие")) -> прочие | W17: =Таблица2[[#This Row],[Площадь, м2]]*Таблица2[[#This Row],[Капитальность]] -> 0.68875 | X17: =IF(AB17<4%,5,IF(AB17<9%,4.5,IF(AB17<14%,4,IF(AB17<24%,3.5,IF(AB17<40%,3,IF(AB17<60%,2.5,IF(AB17<80%,2,1))))))) -> 2.5 | Y17: =X17*Таблица2[[#This Row],[Площадь, м2]] -> 34.4375 | Z17: =Y17*Таблица2[[#This Row],[Капитальность]] -> 1.721875 | AB17: 0.5
